[META]
version=100
spawnOnBlockType=2
spawnSunlight=True
spawnDarkness=False
spawnWater=False
spawnLava=False
underFill=True
randomRotation=True
dig=True
tree=False
branch=False
needsFoundation=True
rarity=100
collisionPercentage=2
spawnElevationMin=0
spawnElevationMax=500
spawnInBiome=Forest,ForestHills
[DATA]
0,0,0:17.0
-1,0,0:17.0
0,1,0:17.0
1,0,0:17.0
0,-1,0:17.0
0,0,1:17.0
-1,0,1:17.0
-1,1,1:17.0
0,1,1:17.0
1,1,1:17.0
1,0,1:17.0
1,-1,1:17.0
0,-1,1:17.0
-1,-1,1:17.0
-1,0,2:17.0
-1,1,2:17.0
0,1,2:17.0
0,0,2:17.0
1,0,2:17.0
0,-1,2:17.0
-1,-1,2:17.0
0,-1,3:17.0
-1,-1,3:17.0
-1,0,3:17.0
0,0,3:17.0
1,0,3:17.0
1,-1,3:17.0
0,1,3:17.0
-1,1,3:17.0
0,-1,4:17.0
-1,-1,4:17.0
-1,0,4:17.0
1,-1,4:17.0
1,0,4:17.0
0,0,4:17.0
0,1,4:17.0
0,0,5:17.0
-1,-1,5:17.0
0,-1,5:17.0
1,-1,5:17.0
1,0,5:17.0
2,0,5:17.0
2,-1,5:17.0
1,-2,5:17.0
2,-2,5:17.0
1,-1,6:17.0
1,-2,6:17.0
2,-2,6:17.0
2,-1,6:17.0
2,0,6:17.0
0,-1,6:17.0
1,-2,7:17.0
1,-1,7:17.0
2,-1,7:17.0
2,0,7:17.0
2,-2,7:17.0
1,-2,8:17.0
2,-2,8:17.0
2,-1,8:17.0
1,-1,8:17.0
1,-2,9:17.0
2,-2,9:17.0
2,-1,9:17.0
1,-1,9:17.0
1,-2,10:17.0
1,-1,10:17.0
2,-2,10:17.0
2,-1,10:17.0
0,-2,10:18.0
0,-1,10:18.0
1,-3,10:18.0
2,-3,10:18.0
3,-2,10:18.0
3,-1,10:18.0
2,0,10:18.0
1,0,10:18.0
1,-2,11:17.0
1,-1,11:17.0
2,-1,11:17.0
2,-2,11:17.0
3,-2,11:18.0
3,-1,11:18.0
2,-3,11:18.0
1,-3,11:18.0
0,-2,11:18.0
0,-1,11:18.0
1,0,11:18.0
2,0,11:18.0
-1,-2,11:18.0
-1,-1,11:18.0
0,-3,11:18.0
1,-4,11:18.0
2,-4,11:18.0
3,-3,11:18.0
4,-2,11:18.0
4,-1,11:18.0
3,0,11:18.0
0,0,11:18.0
1,1,11:18.0
2,1,11:18.0
1,-2,12:17.0
1,-1,12:17.0
2,-1,12:17.0
2,-2,12:17.0
0,-2,12:18.0
0,-1,12:18.0
1,-3,12:18.0
2,-3,12:18.0
3,-2,12:18.0
3,-1,12:18.0
2,0,12:18.0
1,0,12:18.0
0,-3,12:18.0
-1,-2,12:18.0
-1,-1,12:18.0
0,0,12:18.0
1,1,12:18.0
2,1,12:18.0
3,0,12:18.0
4,-1,12:18.0
4,-2,12:18.0
3,-3,12:18.0
2,-4,12:18.0
1,-4,12:18.0
1,-2,13:17.0
1,-1,13:17.0
2,-1,13:17.0
2,-2,13:17.0
0,-3,13:18.0
0,-2,13:18.0
0,-1,13:18.0
0,0,13:18.0
1,1,13:18.0
1,0,13:18.0
2,0,13:18.0
3,0,13:18.0
3,-1,13:18.0
3,-2,13:18.0
3,-3,13:18.0
2,-4,13:18.0
1,-4,13:18.0
1,-3,13:18.0
2,-3,13:18.0
-1,-2,13:18.0
-1,-1,13:18.0
4,-1,13:18.0
4,-2,13:18.0
4,-3,13:18.0
2,1,13:18.0
1,-2,14:17.0
1,-1,14:17.0
2,-1,14:17.0
2,-2,14:17.0
4,-3,14:18.0
4,-2,14:18.0
4,-1,14:18.0
4,0,14:18.0
3,-4,14:18.0
2,-4,14:18.0
1,-4,14:18.0
0,-4,14:18.0
-1,-3,14:18.0
-1,-2,14:18.0
-1,-1,14:18.0
-1,0,14:18.0
0,1,14:18.0
0,0,14:18.0
0,-1,14:18.0
0,-2,14:18.0
0,-3,14:18.0
1,-3,14:18.0
2,-3,14:18.0
3,-3,14:18.0
3,-2,14:18.0
3,-1,14:18.0
3,0,14:18.0
2,0,14:18.0
1,0,14:18.0
1,1,14:18.0
2,1,14:18.0
3,1,14:18.0
1,-2,15:17.0
1,-1,15:17.0
2,-1,15:17.0
2,-2,15:17.0
3,-4,15:18.0
3,-3,15:18.0
3,-2,15:18.0
3,-1,15:18.0
3,0,15:18.0
3,1,15:18.0
2,1,15:18.0
1,1,15:18.0
1,0,15:18.0
0,0,15:18.0
-1,0,15:18.0
2,0,15:18.0
0,1,15:18.0
0,-1,15:18.0
-1,-1,15:18.0
-1,-2,15:18.0
-1,-3,15:18.0
0,-3,15:18.0
0,-2,15:18.0
0,-4,15:18.0
1,-4,15:18.0
2,-4,15:18.0
2,-3,15:18.0
1,-3,15:18.0
4,-2,15:18.0
4,-1,15:18.0
4,-3,15:18.0
4,0,15:18.0
1,-2,16:17.0
1,-1,16:17.0
2,-1,16:17.0
2,-2,16:17.0
4,-3,16:18.0
4,-2,16:18.0
4,-1,16:18.0
4,0,16:18.0
3,0,16:18.0
3,1,16:18.0
2,1,16:18.0
1,1,16:18.0
0,1,16:18.0
0,0,16:18.0
-1,0,16:18.0
-1,-1,16:18.0
-1,-2,16:18.0
-1,-3,16:18.0
0,-3,16:18.0
0,-4,16:18.0
1,-4,16:18.0
2,-4,16:18.0
3,-4,16:18.0
3,-3,16:18.0
3,-2,16:18.0
3,-1,16:18.0
2,0,16:18.0
0,-1,16:18.0
1,0,16:18.0
0,-2,16:18.0
1,-3,16:18.0
2,-3,16:18.0
1,-2,17:17.0
1,-1,17:17.0
2,-1,17:17.0
2,-2,17:17.0
3,-4,17:18.0
3,-3,17:18.0
3,-2,17:18.0
3,-1,17:18.0
3,0,17:18.0
3,1,17:18.0
4,0,17:18.0
4,-1,17:18.0
4,-2,17:18.0
4,-3,17:18.0
2,-3,17:18.0
2,-4,17:18.0
1,-4,17:18.0
0,-4,17:18.0
0,-3,17:18.0
1,-3,17:18.0
-1,-3,17:18.0
-1,-2,17:18.0
-1,-1,17:18.0
-1,0,17:18.0
0,0,17:18.0
0,-1,17:18.0
0,-2,17:18.0
0,1,17:18.0
1,1,17:18.0
2,1,17:18.0
2,0,17:18.0
1,0,17:18.0
1,-2,18:17.0
1,-1,18:17.0
2,-1,18:17.0
2,-2,18:17.0
-1,-3,18:18.0
-1,-2,18:18.0
-1,-1,18:18.0
-1,0,18:18.0
0,0,18:18.0
0,-1,18:18.0
0,-2,18:18.0
0,-3,18:18.0
0,-4,18:18.0
1,-4,18:18.0
2,-4,18:18.0
3,-4,18:18.0
2,-3,18:18.0
1,-3,18:18.0
3,-3,18:18.0
4,-3,18:18.0
4,-2,18:18.0
4,-1,18:18.0
3,-1,18:18.0
3,0,18:18.0
4,0,18:18.0
3,-2,18:18.0
3,1,18:18.0
2,1,18:18.0
1,1,18:18.0
0,1,18:18.0
2,0,18:18.0
1,0,18:18.0
1,-2,19:17.0
1,-1,19:17.0
2,-1,19:17.0
2,-2,19:17.0
-1,-3,19:18.0
-1,-2,19:18.0
-1,-1,19:18.0
-1,0,19:18.0
0,0,19:18.0
0,-1,19:18.0
0,-2,19:18.0
0,-3,19:18.0
0,-4,19:18.0
1,-4,19:18.0
2,-4,19:18.0
3,-4,19:18.0
3,-3,19:18.0
3,-2,19:18.0
2,-3,19:18.0
1,-3,19:18.0
4,-3,19:18.0
4,-2,19:18.0
4,-1,19:18.0
4,0,19:18.0
3,0,19:18.0
3,-1,19:18.0
2,0,19:18.0
2,1,19:18.0
3,1,19:18.0
1,1,19:18.0
0,1,19:18.0
1,0,19:18.0
1,-2,20:17.0
1,-1,20:17.0
2,-1,20:17.0
2,-2,20:17.0
0,-4,20:18.0
0,-3,20:18.0
0,-2,20:18.0
0,-1,20:18.0
0,0,20:18.0
0,1,20:18.0
1,1,20:18.0
2,1,20:18.0
3,1,20:18.0
3,0,20:18.0
3,-1,20:18.0
3,-2,20:18.0
3,-3,20:18.0
3,-4,20:18.0
2,-4,20:18.0
1,-4,20:18.0
1,-3,20:18.0
2,-3,20:18.0
4,-3,20:18.0
4,-2,20:18.0
4,-1,20:18.0
4,0,20:18.0
2,0,20:18.0
1,0,20:18.0
-1,0,20:18.0
-1,-1,20:18.0
-1,-2,20:18.0
-1,-3,20:18.0
1,-2,21:17.0
1,-1,21:17.0
2,-1,21:17.0
2,-2,21:17.0
-1,-2,21:18.0
-1,-1,21:18.0
0,-1,21:18.0
0,-2,21:18.0
0,-3,21:18.0
1,-4,21:18.0
2,-4,21:18.0
3,-2,21:18.0
4,-2,21:18.0
3,-1,21:18.0
3,0,21:18.0
2,1,21:18.0
1,1,21:18.0
0,0,21:18.0
1,0,21:18.0
2,0,21:18.0
4,-1,21:18.0
2,-3,21:18.0
1,-3,21:18.0
3,-3,21:18.0
1,-2,22:17.0
1,-1,22:17.0
2,-1,22:17.0
2,-2,22:17.0
0,-3,22:18.0
0,-2,22:18.0
0,-1,22:18.0
0,0,22:18.0
1,1,22:18.0
2,1,22:18.0
3,0,22:18.0
2,0,22:18.0
1,0,22:18.0
4,-1,22:18.0
4,-2,22:18.0
3,-2,22:18.0
3,-1,22:18.0
3,-3,22:18.0
2,-3,22:18.0
1,-3,22:18.0
1,-4,22:18.0
-1,-2,22:18.0
-1,-1,22:18.0
2,-4,22:18.0
-1,-2,23:18.0
-1,-1,23:18.0
0,-1,23:18.0
0,-2,23:18.0
0,-3,23:18.0
1,-3,23:18.0
1,-4,23:18.0
2,-4,23:18.0
2,-3,23:18.0
3,-3,23:18.0
3,-2,23:18.0
3,-1,23:18.0
4,-1,23:18.0
4,-2,23:18.0
3,0,23:18.0
2,0,23:18.0
2,1,23:18.0
1,1,23:18.0
1,0,23:18.0
0,0,23:18.0
1,-2,23:17.0
1,-1,23:17.0
2,-1,23:17.0
2,-2,23:17.0
1,0,24:18.0
2,0,24:18.0
0,-1,24:18.0
0,-2,24:18.0
1,-3,24:18.0
2,-3,24:18.0
3,-2,24:18.0
3,-1,24:18.0
2,-4,24:18.0
1,-4,24:18.0
-1,-1,24:18.0
-1,-2,24:18.0
2,1,24:18.0
1,1,24:18.0
4,-1,24:18.0
4,-2,24:18.0
0,0,24:18.0
0,-3,24:18.0
3,-3,24:18.0
3,0,24:18.0
1,-2,24:17.0
1,-1,24:17.0
2,-1,24:17.0
2,-2,24:17.0
3,-2,25:18.0
3,-1,25:18.0
4,-1,25:18.0
4,-2,25:18.0
2,-3,25:18.0
1,-3,25:18.0
1,-4,25:18.0
2,-4,25:18.0
0,-2,25:18.0
0,-1,25:18.0
-1,-1,25:18.0
-1,-2,25:18.0
1,0,25:18.0
2,0,25:18.0
2,1,25:18.0
1,1,25:18.0
1,-1,25:17.0
2,-1,25:17.0
2,-2,25:17.0
1,-2,25:17.0
1,-2,26:18.0
1,-1,26:18.0
2,-1,26:18.0
2,-2,26:18.0
1,-2,27:18.0
1,-1,27:18.0
2,-1,27:18.0
2,-2,27:18.0
