[META]
version=100
spawnOnBlockType=2
spawnSunlight=True
spawnDarkness=False
spawnWater=False
spawnLava=False
underFill=True
randomRotation=True
dig=True
tree=False
branch=False
needsFoundation=True
rarity=100
collisionPercentage=2
spawnElevationMin=0
spawnElevationMax=500
spawnInBiome=Swampland
[DATA]
1,1,0:17.0
0,2,0:17.0
2,0,0:17.0
0,1,0:17.0
1,0,0:17.0
0,0,0:17.0
-1,1,0:17.0
1,-1,0:17.0
0,-1,0:17.0
0,-2,0:17.0
-1,-1,0:17.0
-1,0,0:17.0
2,0,1:17.0
0,2,1:17.0
0,1,1:17.0
1,0,1:17.0
0,0,1:17.0
1,-1,1:17.0
0,-1,1:17.0
-1,0,1:17.0
1,2,-1:17.0
2,2,-1:17.0
2,1,-1:17.0
0,1,2:17.0
1,0,2:17.0
0,0,2:17.0
0,-1,2:17.0
-1,0,2:17.0
0,0,3:17.0
0,0,4:17.0
-1,0,4:18.0
-1,1,4:18.0
0,1,4:18.0
0,0,5:17.0
1,0,5:18.0
0,-1,5:18.0
1,1,5:18.0
0,1,5:18.0
-1,0,5:18.0
-1,-1,5:18.0
0,0,6:17.0
-1,-1,6:18.0
-1,0,6:18.0
0,-1,6:18.0
1,-1,6:18.0
1,0,6:18.0
1,1,6:18.0
0,1,6:18.0
0,0,7:17.0
1,1,7:18.0
1,2,7:18.0
2,2,7:18.0
2,1,7:18.0
0,1,7:18.0
1,0,7:18.0
1,-1,7:18.0
0,-1,7:18.0
-1,0,7:18.0
-1,1,7:18.0
-1,-1,7:18.0
-2,0,7:18.0
-2,-1,7:18.0
-1,-2,7:18.0
0,-2,7:18.0
1,-2,7:18.0
2,-1,7:18.0
2,0,7:18.0
0,2,7:18.0
0,-1,8:18.0
-1,-1,8:18.0
-1,0,8:18.0
-1,1,8:18.0
0,1,8:18.0
0,2,8:18.0
1,2,8:18.0
1,1,8:18.0
2,1,8:18.0
2,0,8:18.0
1,0,8:18.0
1,-1,8:18.0
-1,-2,8:18.0
0,-2,8:18.0
-2,0,8:18.0
-2,-1,8:18.0
0,0,8:17.0
-1,-1,9:18.0
-1,0,9:18.0
0,-1,9:18.0
0,0,9:17.0
1,0,9:18.0
1,1,9:18.0
2,1,9:18.0
2,0,9:18.0
1,2,9:18.0
0,2,9:18.0
0,1,9:18.0
-1,1,9:18.0
-2,0,9:18.0
-2,-1,9:18.0
-1,-2,9:18.0
0,-2,9:18.0
1,-1,9:18.0
0,-1,10:18.0
-1,-1,10:18.0
-1,0,10:18.0
-1,1,10:18.0
0,1,10:18.0
1,1,10:18.0
1,0,10:18.0
0,0,10:17.0
0,2,10:18.0
-1,0,11:18.0
-2,0,11:18.0
-1,-1,11:18.0
0,0,11:18.0
0,-1,11:18.0
0,1,11:18.0
-1,1,11:18.0
0,2,11:18.0
1,1,11:18.0
