[META]
version=100
spawnOnBlockType=155,79
spawnSunlight=True
spawnDarkness=False
spawnWater=False
spawnLava=False
underFill=True
randomRotation=True
dig=True
tree=False
branch=False
needsFoundation=True
rarity=100
collisionPercentage=2
spawnElevationMin=0
spawnElevationMax=500
spawnInBiome=Plains
[DATA]
0,0,0:17.2
0,1,0:17.2
1,1,0:17.2
1,0,0:17.2
1,-1,0:17.2
0,-1,0:17.2
-1,0,0:17.2
-1,1,0:17.2
0,2,0:17.2
1,2,0:17.2
2,1,0:17.2
2,0,0:17.2
1,0,1:17.2
1,1,1:17.2
0,1,1:17.2
0,0,1:17.2
-1,0,1:17.2
-1,1,1:17.2
0,2,1:17.2
1,2,1:17.2
2,1,1:17.2
2,0,1:17.2
1,-1,1:17.2
0,-1,1:17.2
0,-1,2:17.2
0,0,2:17.2
0,1,2:17.2
0,2,2:17.2
1,1,2:17.2
2,1,2:17.2
-1,0,2:17.2
1,0,2:17.2
0,0,3:17.2
0,1,3:17.2
1,1,3:17.2
1,0,3:17.2
0,0,4:17.2
0,1,4:17.2
1,1,4:17.2
1,0,4:17.2
0,0,5:17.2
0,1,5:17.2
1,1,5:17.2
1,0,5:17.2
0,0,6:17.2
0,1,6:17.2
1,1,6:17.2
1,0,6:17.2
0,0,7:17.2
0,1,7:17.2
1,1,7:17.2
1,0,7:17.2
0,0,8:17.2
0,1,8:17.2
1,1,8:17.2
1,0,8:17.2
0,0,9:17.2
0,1,9:17.2
1,1,9:17.2
1,0,9:17.2
0,0,10:17.2
0,1,10:17.2
1,1,10:17.2
1,0,10:17.2
0,0,11:17.2
0,1,11:17.2
1,1,11:17.2
1,0,11:17.2
0,0,12:17.2
0,1,12:17.2
1,1,12:17.2
1,0,12:17.2
0,0,13:17.2
0,1,13:17.2
1,1,13:17.2
1,0,13:17.2
0,0,14:17.2
0,1,14:17.2
1,1,14:17.2
1,0,14:17.2
0,0,15:17.2
0,1,15:17.2
1,1,15:17.2
1,0,15:17.2
0,0,16:17.2
0,1,16:17.2
1,1,16:17.2
1,0,16:17.2
0,0,17:17.2
0,1,17:17.2
1,1,17:17.2
1,0,17:17.2
0,0,18:17.2
0,1,18:17.2
1,1,18:17.2
1,0,18:17.2
0,0,19:17.2
0,1,19:17.2
1,1,19:17.2
1,0,19:17.2
0,0,20:18.2
0,1,20:18.2
1,1,20:18.2
1,0,20:18.2
1,-1,20:18.2
0,-1,20:18.2
-1,0,20:18.2
-1,1,20:18.2
1,2,20:18.2
0,2,20:18.2
2,1,20:18.2
2,0,20:18.2
2,-1,20:18.2
3,0,20:18.2
3,-1,20:18.2
2,-2,20:18.2
1,-2,20:18.2
3,-2,20:18.2
1,-1,21:18.2
0,-1,21:18.2
0,0,21:18.2
-1,0,21:18.2
-1,-1,21:18.2
0,-2,21:18.2
1,-2,21:18.2
1,-3,21:18.2
2,-3,21:18.2
3,-3,21:18.2
4,-3,21:18.2
4,-2,21:18.2
3,-2,21:18.2
3,-1,21:18.2
4,-1,21:18.2
2,-2,21:18.2
2,-1,21:18.2
3,0,21:18.2
4,0,21:18.2
3,1,21:18.2
4,1,21:18.2
3,2,21:18.2
2,2,21:18.2
2,3,21:18.2
1,3,21:18.2
0,3,21:18.2
-1,3,21:18.2
-1,2,21:18.2
-2,2,21:18.2
-2,1,21:18.2
-2,0,21:18.2
-2,-1,21:18.2
-1,-2,21:18.2
-1,1,21:18.2
0,1,21:18.2
0,2,21:18.2
1,2,21:18.2
1,1,21:18.2
2,1,21:18.2
2,0,21:18.2
1,0,21:18.2
-2,-1,22:18.2
-3,-1,22:18.2
-3,0,22:18.2
-3,1,22:18.2
-3,2,22:18.2
-3,3,22:18.2
-2,3,22:18.2
-2,4,22:18.2
-1,4,22:18.2
0,4,22:18.2
1,4,22:18.2
2,4,22:18.2
3,4,22:18.2
3,3,22:18.2
4,3,22:18.2
4,2,22:18.2
5,2,22:18.2
5,1,22:18.2
5,0,22:18.2
5,-1,22:18.2
5,-2,22:18.2
4,-3,22:18.2
3,-4,22:18.2
2,-4,22:18.2
1,-4,22:18.2
0,-4,22:18.2
0,-3,22:18.2
-1,-3,22:18.2
-1,-2,22:18.2
-2,-2,22:18.2
-2,-3,22:18.2
4,-2,22:18.2
4,-1,22:18.2
4,1,22:18.2
4,0,22:18.2
3,-2,22:18.2
3,-3,22:18.2
2,-3,22:18.2
2,-2,22:18.2
2,-1,22:18.2
1,0,22:18.2
2,0,22:18.2
2,1,22:18.2
3,1,22:18.2
1,-2,22:18.2
1,-1,22:18.2
1,1,22:18.2
2,2,22:18.2
3,2,22:18.2
3,-1,22:18.2
3,0,22:18.2
1,2,22:18.2
1,3,22:18.2
2,3,22:18.2
0,3,22:18.2
-1,3,22:18.2
-2,2,22:18.2
-2,1,22:18.2
-1,2,22:18.2
-1,1,22:18.2
0,1,22:18.2
0,0,22:18.2
0,-1,22:18.2
-1,-1,22:18.2
-1,0,22:18.2
-2,0,22:18.2
0,2,22:18.2
1,-3,22:18.2
0,-2,22:18.2
0,-3,23:18.2
0,-4,23:18.2
1,-4,23:18.2
2,-4,23:18.2
3,-4,23:18.2
5,-2,23:18.2
5,-1,23:18.2
5,0,23:18.2
5,1,23:18.2
5,2,23:18.2
4,2,23:18.2
4,3,23:18.2
3,3,23:18.2
2,3,23:18.2
2,4,23:18.2
3,4,23:18.2
1,4,23:18.2
0,4,23:18.2
-1,4,23:18.2
-2,4,23:18.2
-2,3,23:18.2
-2,2,23:18.2
-3,3,23:18.2
-3,2,23:18.2
-3,1,23:18.2
-3,0,23:18.2
-3,-1,23:18.2
-2,-1,23:18.2
-2,-2,23:18.2
-2,-3,23:18.2
-1,-2,23:18.2
0,-2,23:18.2
-1,-3,23:18.2
-1,-1,23:18.2
-2,0,23:18.2
-2,1,23:18.2
-1,1,23:18.2
-1,0,23:18.2
0,0,23:18.2
-1,2,23:18.2
0,1,23:18.2
0,-1,23:18.2
0,2,23:18.2
1,1,23:18.2
1,0,23:18.2
1,-1,23:18.2
1,-2,23:18.2
0,3,23:18.2
-1,3,23:18.2
1,2,23:18.2
1,3,23:18.2
2,2,23:18.2
2,1,23:18.2
3,0,23:18.2
3,-1,23:18.2
2,-1,23:18.2
3,-2,23:18.2
3,1,23:18.2
4,1,23:18.2
4,-1,23:18.2
4,0,23:18.2
4,-2,23:18.2
3,2,23:18.2
4,-3,23:18.2
3,-3,23:18.2
2,-2,23:18.2
2,0,23:18.2
2,-3,23:18.2
1,-3,23:18.2
0,-4,24:18.2
0,-3,24:18.2
0,-2,24:18.2
0,-1,24:18.2
0,0,24:18.2
0,1,24:18.2
0,2,24:18.2
0,3,24:18.2
0,4,24:18.2
1,4,24:18.2
2,4,24:18.2
3,4,24:18.2
3,3,24:18.2
4,3,24:18.2
4,2,24:18.2
5,2,24:18.2
5,1,24:18.2
5,0,24:18.2
5,-1,24:18.2
5,-2,24:18.2
3,-4,24:18.2
2,-4,24:18.2
1,-4,24:18.2
1,-3,24:18.2
1,-2,24:18.2
1,-1,24:18.2
1,0,24:18.2
1,1,24:18.2
1,2,24:18.2
1,3,24:18.2
2,3,24:18.2
3,2,24:18.2
3,1,24:18.2
3,0,24:18.2
3,-1,24:18.2
3,-2,24:18.2
3,-3,24:18.2
2,-3,24:18.2
2,-2,24:18.2
2,-1,24:18.2
2,0,24:18.2
2,1,24:18.2
2,2,24:18.2
4,1,24:18.2
4,0,24:18.2
4,-1,24:18.2
4,-2,24:18.2
4,-3,24:18.2
-1,-3,24:18.2
-2,-3,24:18.2
-2,-2,24:18.2
-2,-1,24:18.2
-3,-1,24:18.2
-3,0,24:18.2
-3,1,24:18.2
-3,2,24:18.2
-3,3,24:18.2
-2,3,24:18.2
-2,4,24:18.2
-1,4,24:18.2
-1,3,24:18.2
-1,2,24:18.2
-1,1,24:18.2
-1,0,24:18.2
-1,-1,24:18.2
-1,-2,24:18.2
-2,0,24:18.2
-2,1,24:18.2
-2,2,24:18.2
-2,-1,25:18.2
-2,0,25:18.2
-2,1,25:18.2
-2,2,25:18.2
-1,2,25:18.2
-1,3,25:18.2
0,3,25:18.2
1,3,25:18.2
2,3,25:18.2
2,2,25:18.2
3,2,25:18.2
4,2,25:18.2
4,1,25:18.2
4,0,25:18.2
4,-1,25:18.2
4,-2,25:18.2
3,-2,25:18.2
3,-3,25:18.2
2,-3,25:18.2
1,-2,25:18.2
0,-2,25:18.2
-1,-2,25:18.2
-1,-3,25:18.2
0,-3,25:18.2
1,-3,25:18.2
3,-1,25:18.2
3,0,25:18.2
3,1,25:18.2
2,-2,25:18.2
2,-1,25:18.2
1,-1,25:18.2
1,0,25:18.2
1,1,25:18.2
1,2,25:18.2
2,1,25:18.2
2,0,25:18.2
0,0,25:18.2
0,-1,25:18.2
-1,-1,25:18.2
-1,0,25:18.2
-1,1,25:18.2
0,1,25:18.2
0,2,25:18.2
-1,0,26:18.2
0,0,26:18.2
0,1,26:18.2
0,-1,26:18.2
1,-1,26:18.2
1,0,26:18.2
2,0,26:18.2
2,-1,26:18.2
1,-2,26:18.2
1,1,26:18.2
3,0,26:18.2
1,0,27:18.2
